<?xml version="1.0" encoding="utf-8"?>
<!-- This URDF was automatically created by SolidWorks to URDF Exporter! Originally created by Stephen Brawner (brawner@gmail.com) 
     Commit Version: 1.6.0-4-g7f85cfe  Build Version: 1.6.7995.38578
     For more information, please see http://wiki.ros.org/sw_urdf_exporter -->
<robot
  name="r2000_urdf">
  <link
    name="base">
    <inertial>
      <origin
        xyz="-0.0589648663227796 0.134200116749551 0.00547458963371417"
        rpy="0 0 0" />
      <mass
        value="79.4265587442076" />
      <inertia
        ixx="2.15281121006603"
        ixy="-0.11329003960186"
        ixz="-0.0256118794044203"
        iyy="4.1807420330578"
        iyz="0.00754987522675796"
        izz="3.2718961321262" />
    </inertial>
    <visual>
      <origin
        xyz="0 0 0"
        rpy="0 0 0" />
      <geometry>
        <mesh
          filename="package://r2000_urdf/meshes/base.STL" />
      </geometry>
      <material
        name="">
        <color
          rgba="0.792156862745098 0.819607843137255 0.933333333333333 1" />
      </material>
    </visual>
    <collision>
      <origin
        xyz="0 0 0"
        rpy="0 0 0" />
      <geometry>
        <mesh
          filename="package://r2000_urdf/meshes/base.STL" />
      </geometry>
    </collision>
  </link>
  <link
    name="link1">
    <inertial>
      <origin
        xyz="-0.0146188551218751 0.261336311721324 -0.0778801226933692"
        rpy="0 0 0" />
      <mass
        value="98.4447414677161" />
      <inertia
        ixx="3.54015126212754"
        ixy="-1.04534649523983"
        ixz="-0.544926692252298"
        iyy="5.14719282768335"
        iyz="-0.335394603229195"
        izz="4.95454477813311" />
    </inertial>
    <visual>
      <origin
        xyz="0 0 0"
        rpy="0 0 0" />
      <geometry>
        <mesh
          filename="package://r2000_urdf/meshes/link1.STL" />
      </geometry>
      <material
        name="">
        <color
          rgba="0.792156862745098 0.819607843137255 0.933333333333333 1" />
      </material>
    </visual>
    <collision>
      <origin
        xyz="0 0 0"
        rpy="0 0 0" />
      <geometry>
        <mesh
          filename="package://r2000_urdf/meshes/link1.STL" />
      </geometry>
    </collision>
  </link>
  <joint
    name="joint1"
    type="continuous">
    <origin
      xyz="0 0.299 0"
      rpy="0 0 0" />
    <parent
      link="base" />
    <child
      link="link1" />
    <axis
      xyz="0 1 0" />
  </joint>
  <link
    name="link2">
    <inertial>
      <origin
        xyz="0.0428715316339108 0.424830287877023 -0.160333088027016"
        rpy="0 0 0" />
      <mass
        value="57.8340183615569" />
      <inertia
        ixx="7.20323248318394"
        ixy="-0.251100382441449"
        ixz="0.0219359368413988"
        iyy="0.770569300243738"
        iyz="0.795643805567422"
        izz="7.39893614081204" />
    </inertial>
    <visual>
      <origin
        xyz="0 0 0"
        rpy="0 0 0" />
      <geometry>
        <mesh
          filename="package://r2000_urdf/meshes/link2.STL" />
      </geometry>
      <material
        name="">
        <color
          rgba="0.792156862745098 0.819607843137255 0.933333333333333 1" />
      </material>
    </visual>
    <collision>
      <origin
        xyz="0 0 0"
        rpy="0 0 0" />
      <geometry>
        <mesh
          filename="package://r2000_urdf/meshes/link2.STL" />
      </geometry>
    </collision>
  </link>
  <joint
    name="joint2"
    type="continuous">
    <origin
      xyz="0.312 0.371 -0.056"
      rpy="0 0 0" />
    <parent
      link="link1" />
    <child
      link="link2" />
    <axis
      xyz="0 0 -1" />
  </joint>
  <link
    name="link3">
    <inertial>
      <origin
        xyz="0.376115797097515 0.145322344936816 0.196717251272584"
        rpy="0 0 0" />
      <mass
        value="62.7672796425545" />
      <inertia
        ixx="1.55328036855659"
        ixy="-1.75404342962931"
        ixz="-0.697791755533549"
        iyy="14.4666505631054"
        iyz="-0.267307649232387"
        izz="14.8007887231282" />
    </inertial>
    <visual>
      <origin
        xyz="0 0 0"
        rpy="0 0 0" />
      <geometry>
        <mesh
          filename="package://r2000_urdf/meshes/link3.STL" />
      </geometry>
      <material
        name="">
        <color
          rgba="0.792156862745098 0.819607843137255 0.933333333333333 1" />
      </material>
    </visual>
    <collision>
      <origin
        xyz="0 0 0"
        rpy="0 0 0" />
      <geometry>
        <mesh
          filename="package://r2000_urdf/meshes/link3.STL" />
      </geometry>
    </collision>
  </link>
  <joint
    name="joint3"
    type="continuous">
    <origin
      xyz="0 1.075 -0.17515"
      rpy="0 0 0" />
    <parent
      link="link2" />
    <child
      link="link3" />
    <axis
      xyz="0 0 1" />
  </joint>
  <link
    name="link4">
    <inertial>
      <origin
        xyz="0.125532432466578 -1.86065542973068E-08 -0.0240014962921646"
        rpy="0 0 0" />
      <mass
        value="3.77391712485386" />
      <inertia
        ixx="0.0103907506880208"
        ixy="7.26008866017942E-10"
        ixz="-0.00294677051456163"
        iyy="0.0361687859556413"
        iyz="4.8529452733311E-09"
        izz="0.0358501296030016" />
    </inertial>
    <visual>
      <origin
        xyz="0 0 0"
        rpy="0 0 0" />
      <geometry>
        <mesh
          filename="package://r2000_urdf/meshes/link4.STL" />
      </geometry>
      <material
        name="">
        <color
          rgba="0.866666666666667 0.866666666666667 0 1" />
      </material>
    </visual>
    <collision>
      <origin
        xyz="0 0 0"
        rpy="0 0 0" />
      <geometry>
        <mesh
          filename="package://r2000_urdf/meshes/link4.STL" />
      </geometry>
    </collision>
  </link>
  <joint
    name="joint4"
    type="continuous">
    <origin
      xyz="1.499 0.225 0.26215"
      rpy="0 0 0" />
    <parent
      link="link3" />
    <child
      link="link4" />
    <axis
      xyz="1 0 0" />
  </joint>
  <link
    name="link5">
    <inertial>
      <origin
        xyz="0.0543158465023166 2.98365998574468E-10 -0.0587496229396575"
        rpy="0 0 0" />
      <mass
        value="6.55493498459228" />
      <inertia
        ixx="0.0581704674231251"
        ixy="-6.30093205715802E-11"
        ixz="0.0155297667861974"
        iyy="0.082931324304848"
        iyz="2.51023794909951E-11"
        izz="0.0545737275436082" />
    </inertial>
    <visual>
      <origin
        xyz="0 0 0"
        rpy="0 0 0" />
      <geometry>
        <mesh
          filename="package://r2000_urdf/meshes/link5.STL" />
      </geometry>
      <material
        name="">
        <color
          rgba="0.792156862745098 0.819607843137255 0.933333333333333 1" />
      </material>
    </visual>
    <collision>
      <origin
        xyz="0 0 0"
        rpy="0 0 0" />
      <geometry>
        <mesh
          filename="package://r2000_urdf/meshes/link5.STL" />
      </geometry>
    </collision>
  </link>
  <joint
    name="joint5"
    type="continuous">
    <origin
      xyz="0.231 0 0.0605"
      rpy="0 0 0" />
    <parent
      link="link4" />
    <child
      link="link5" />
    <axis
      xyz="0 0 -1" />
  </joint>
  <link
    name="link6">
    <inertial>
      <origin
        xyz="0.0188963612278803 0 -0.0310752861847552"
        rpy="0 0 0" />
      <mass
        value="0.522292001248235" />
      <inertia
        ixx="0.00143474809666454"
        ixy="3.49428873747403E-21"
        ixz="4.85762026974708E-07"
        iyy="0.000772279049098994"
        iyz="-3.18249216211323E-20"
        izz="0.000772450968594439" />
    </inertial>
    <visual>
      <origin
        xyz="0 0 0"
        rpy="0 0 0" />
      <geometry>
        <mesh
          filename="package://r2000_urdf/meshes/link6.STL" />
      </geometry>
      <material
        name="">
        <color
          rgba="0.792156862745098 0.819607843137255 0.933333333333333 1" />
      </material>
    </visual>
    <collision>
      <origin
        xyz="0 0 0"
        rpy="0 0 0" />
      <geometry>
        <mesh
          filename="package://r2000_urdf/meshes/link6.STL" />
      </geometry>
    </collision>
  </link>
  <joint
    name="joint6"
    type="continuous">
    <origin
      xyz="0.179500000000001 0 -0.0605"
      rpy="0 0 0" />
    <parent
      link="link5" />
    <child
      link="link6" />
    <axis
      xyz="1 0 0" />
  </joint>
</robot>